[2025-07-01T14:08:24.472+0000] {taskinstance.py:1956} INFO - Dependencies all met for dep_context=non-requeueable deps ti=<TaskInstance: etl_retail_dag.transform manual__2025-07-01T14:08:06.464710+00:00 [queued]>
[2025-07-01T14:08:24.528+0000] {taskinstance.py:1956} INFO - Dependencies all met for dep_context=requeueable deps ti=<TaskInstance: etl_retail_dag.transform manual__2025-07-01T14:08:06.464710+00:00 [queued]>
[2025-07-01T14:08:24.530+0000] {taskinstance.py:2170} INFO - Starting attempt 1 of 1
[2025-07-01T14:08:24.589+0000] {taskinstance.py:2191} INFO - Executing <Task(PythonOperator): transform> on 2025-07-01 14:08:06.464710+00:00
[2025-07-01T14:08:24.601+0000] {standard_task_runner.py:60} INFO - Started process 220 to run task
[2025-07-01T14:08:24.610+0000] {standard_task_runner.py:87} INFO - Running: ['***', 'tasks', 'run', 'etl_retail_dag', 'transform', 'manual__2025-07-01T14:08:06.464710+00:00', '--job-id', '11', '--raw', '--subdir', 'DAGS_FOLDER/etl_retail.py', '--cfg-path', '/tmp/tmpihphz345']
[2025-07-01T14:08:24.615+0000] {standard_task_runner.py:88} INFO - Job 11: Subtask transform
[2025-07-01T14:08:24.974+0000] {task_command.py:423} INFO - Running <TaskInstance: etl_retail_dag.transform manual__2025-07-01T14:08:06.464710+00:00 [running]> on host 3f084dede7e5
[2025-07-01T14:08:25.459+0000] {taskinstance.py:2480} INFO - Exporting env vars: AIRFLOW_CTX_DAG_OWNER='dewi' AIRFLOW_CTX_DAG_ID='etl_retail_dag' AIRFLOW_CTX_TASK_ID='transform' AIRFLOW_CTX_EXECUTION_DATE='2025-07-01T14:08:06.464710+00:00' AIRFLOW_CTX_TRY_NUMBER='1' AIRFLOW_CTX_DAG_RUN_ID='manual__2025-07-01T14:08:06.464710+00:00'
[2025-07-01T14:08:25.526+0000] {taskinstance.py:2698} ERROR - Task failed with exception
Traceback (most recent call last):
  File "/home/airflow/.local/lib/python3.8/site-packages/pandas/core/indexes/base.py", line 3653, in get_loc
    return self._engine.get_loc(casted_key)
  File "pandas/_libs/index.pyx", line 147, in pandas._libs.index.IndexEngine.get_loc
  File "pandas/_libs/index.pyx", line 176, in pandas._libs.index.IndexEngine.get_loc
  File "pandas/_libs/hashtable_class_helper.pxi", line 7080, in pandas._libs.hashtable.PyObjectHashTable.get_item
  File "pandas/_libs/hashtable_class_helper.pxi", line 7088, in pandas._libs.hashtable.PyObjectHashTable.get_item
KeyError: 'Quantity'

The above exception was the direct cause of the following exception:

Traceback (most recent call last):
  File "/home/airflow/.local/lib/python3.8/site-packages/airflow/models/taskinstance.py", line 433, in _execute_task
    result = execute_callable(context=context, **execute_callable_kwargs)
  File "/home/airflow/.local/lib/python3.8/site-packages/airflow/operators/python.py", line 199, in execute
    return_value = self.execute_callable()
  File "/home/airflow/.local/lib/python3.8/site-packages/airflow/operators/python.py", line 216, in execute_callable
    return self.python_callable(*self.op_args, **self.op_kwargs)
  File "/opt/airflow/dags/etl_retail.py", line 28, in transform_data
    df["TotalPrice"] = df["Quantity"] * df["UnitPrice"]
  File "/home/airflow/.local/lib/python3.8/site-packages/pandas/core/frame.py", line 3761, in __getitem__
    indexer = self.columns.get_loc(key)
  File "/home/airflow/.local/lib/python3.8/site-packages/pandas/core/indexes/base.py", line 3655, in get_loc
    raise KeyError(key) from err
KeyError: 'Quantity'
[2025-07-01T14:08:25.628+0000] {taskinstance.py:1138} INFO - Marking task as FAILED. dag_id=etl_retail_dag, task_id=transform, execution_date=20250701T140806, start_date=20250701T140824, end_date=20250701T140825
[2025-07-01T14:08:25.736+0000] {standard_task_runner.py:107} ERROR - Failed to execute job 11 for task transform ('Quantity'; 220)
[2025-07-01T14:08:25.841+0000] {local_task_job_runner.py:234} INFO - Task exited with return code 1
[2025-07-01T14:08:26.037+0000] {taskinstance.py:3280} INFO - 0 downstream tasks scheduled from follow-on schedule check
