[2025-07-01T13:58:34.005+0000] {taskinstance.py:1956} INFO - Dependencies all met for dep_context=non-requeueable deps ti=<TaskInstance: etl_retail_dag.transform manual__2025-07-01T13:58:28.415798+00:00 [queued]>
[2025-07-01T13:58:34.081+0000] {taskinstance.py:1956} INFO - Dependencies all met for dep_context=requeueable deps ti=<TaskInstance: etl_retail_dag.transform manual__2025-07-01T13:58:28.415798+00:00 [queued]>
[2025-07-01T13:58:34.084+0000] {taskinstance.py:2170} INFO - Starting attempt 1 of 1
[2025-07-01T13:58:34.269+0000] {taskinstance.py:2191} INFO - Executing <Task(PythonOperator): transform> on 2025-07-01 13:58:28.415798+00:00
[2025-07-01T13:58:34.320+0000] {standard_task_runner.py:60} INFO - Started process 242 to run task
[2025-07-01T13:58:34.456+0000] {standard_task_runner.py:87} INFO - Running: ['***', 'tasks', 'run', 'etl_retail_dag', 'transform', 'manual__2025-07-01T13:58:28.415798+00:00', '--job-id', '6', '--raw', '--subdir', 'DAGS_FOLDER/etl_retail.py', '--cfg-path', '/tmp/tmpeizthnh1']
[2025-07-01T13:58:34.473+0000] {standard_task_runner.py:88} INFO - Job 6: Subtask transform
[2025-07-01T13:58:35.293+0000] {task_command.py:423} INFO - Running <TaskInstance: etl_retail_dag.transform manual__2025-07-01T13:58:28.415798+00:00 [running]> on host 3f084dede7e5
[2025-07-01T13:58:36.339+0000] {taskinstance.py:2480} INFO - Exporting env vars: AIRFLOW_CTX_DAG_OWNER='dewi' AIRFLOW_CTX_DAG_ID='etl_retail_dag' AIRFLOW_CTX_TASK_ID='transform' AIRFLOW_CTX_EXECUTION_DATE='2025-07-01T13:58:28.415798+00:00' AIRFLOW_CTX_TRY_NUMBER='1' AIRFLOW_CTX_DAG_RUN_ID='manual__2025-07-01T13:58:28.415798+00:00'
[2025-07-01T13:58:36.407+0000] {taskinstance.py:2698} ERROR - Task failed with exception
Traceback (most recent call last):
  File "/home/airflow/.local/lib/python3.8/site-packages/pandas/core/indexes/base.py", line 3653, in get_loc
    return self._engine.get_loc(casted_key)
  File "pandas/_libs/index.pyx", line 147, in pandas._libs.index.IndexEngine.get_loc
  File "pandas/_libs/index.pyx", line 176, in pandas._libs.index.IndexEngine.get_loc
  File "pandas/_libs/hashtable_class_helper.pxi", line 7080, in pandas._libs.hashtable.PyObjectHashTable.get_item
  File "pandas/_libs/hashtable_class_helper.pxi", line 7088, in pandas._libs.hashtable.PyObjectHashTable.get_item
KeyError: 'Quantity'

The above exception was the direct cause of the following exception:

Traceback (most recent call last):
  File "/home/airflow/.local/lib/python3.8/site-packages/airflow/models/taskinstance.py", line 433, in _execute_task
    result = execute_callable(context=context, **execute_callable_kwargs)
  File "/home/airflow/.local/lib/python3.8/site-packages/airflow/operators/python.py", line 199, in execute
    return_value = self.execute_callable()
  File "/home/airflow/.local/lib/python3.8/site-packages/airflow/operators/python.py", line 216, in execute_callable
    return self.python_callable(*self.op_args, **self.op_kwargs)
  File "/opt/airflow/dags/etl_retail.py", line 25, in transform_data
    df['TotalPrice'] = df['Quantity'] * df['UnitPrice']
  File "/home/airflow/.local/lib/python3.8/site-packages/pandas/core/frame.py", line 3761, in __getitem__
    indexer = self.columns.get_loc(key)
  File "/home/airflow/.local/lib/python3.8/site-packages/pandas/core/indexes/base.py", line 3655, in get_loc
    raise KeyError(key) from err
KeyError: 'Quantity'
[2025-07-01T13:58:36.487+0000] {taskinstance.py:1138} INFO - Marking task as FAILED. dag_id=etl_retail_dag, task_id=transform, execution_date=20250701T135828, start_date=20250701T135834, end_date=20250701T135836
[2025-07-01T13:58:36.549+0000] {standard_task_runner.py:107} ERROR - Failed to execute job 6 for task transform ('Quantity'; 242)
[2025-07-01T13:58:36.599+0000] {local_task_job_runner.py:234} INFO - Task exited with return code 1
[2025-07-01T13:58:36.752+0000] {taskinstance.py:3280} INFO - 0 downstream tasks scheduled from follow-on schedule check
